#usda 1.0
(
    customLayerData = {
        string creator = "URDF USD Converter v0.1.3"
    }
    defaultPrim = "sockbot_base"
    doc = """Generated from Composed Stage of root layer C:\\Users\\vicsh\\AppData\\Local\\Temp\\tmphpyd121q\\sockbot_base.usdc


Generated from Composed Stage of root layer C:\\Users\\vicsh\\AppData\\Local\\Temp\\urdf_import_sockbot_base_tffdq9oq\\usdex_sockbot_base\\sockbot_base.usdc


Generated from Composed Stage of root layer C:\\Users\\vicsh\\AppData\\Local\\Temp\\urdf_import_sockbot_base_tffdq9oq\\temp_sockbot_base\\sockbot_base.usd


Generated from Composed Stage of root layer C:\\Users\\vicsh\\Projects\\lerobot_on_track\\isaac_assets\\sockbot_base\\payloads\\base.usd
"""
    kilogramsPerUnit = 1
    metersPerUnit = 1
    upAxis = "Z"
)

over "sockbot_base"
{
    over "Geometry"
    {
        over "base_link" (
            prepend apiSchemas = ["PhysicsRigidBodyAPI", "PhysicsArticulationRootAPI", "NewtonArticulationRootAPI", "PhysicsMassAPI"]
        )
        {
            bool newton:selfCollisionEnabled = 0
            point3f physics:centerOfMass = (0, 0, 0)
            float3 physics:diagonalInertia = (0.005987, 0.010737, 0.015417)
            float physics:mass = 2.5
            quatf physics:principalAxes = (1, 0, 0, 0)

            over "wheel_front_left" (
                prepend apiSchemas = ["PhysicsRigidBodyAPI", "PhysicsMassAPI"]
            )
            {
                point3f physics:centerOfMass = (0, 0, 0)
                float3 physics:diagonalInertia = (0.000124, 0.000124, 0.000181)
                float physics:mass = 0.25
                quatf physics:principalAxes = (0.70710677, 0.70710677, 0, 0)

                over "cylinder_1" (
                    prepend apiSchemas = ["NewtonCollisionAPI"]
                )
                {
                }
            }

            over "wheel_front_right" (
                prepend apiSchemas = ["PhysicsRigidBodyAPI", "PhysicsMassAPI"]
            )
            {
                point3f physics:centerOfMass = (0, 0, 0)
                float3 physics:diagonalInertia = (0.000124, 0.000124, 0.000181)
                float physics:mass = 0.25
                quatf physics:principalAxes = (0.70710677, 0.70710677, 0, 0)

                over "cylinder_1" (
                    prepend apiSchemas = ["NewtonCollisionAPI"]
                )
                {
                }
            }

            over "wheel_rear_left" (
                prepend apiSchemas = ["PhysicsRigidBodyAPI", "PhysicsMassAPI"]
            )
            {
                point3f physics:centerOfMass = (0, 0, 0)
                float3 physics:diagonalInertia = (0.000124, 0.000124, 0.000181)
                float physics:mass = 0.25
                quatf physics:principalAxes = (0.70710677, 0.70710677, 0, 0)

                over "cylinder_1" (
                    prepend apiSchemas = ["NewtonCollisionAPI"]
                )
                {
                }
            }

            over "wheel_rear_right" (
                prepend apiSchemas = ["PhysicsRigidBodyAPI", "PhysicsMassAPI"]
            )
            {
                point3f physics:centerOfMass = (0, 0, 0)
                float3 physics:diagonalInertia = (0.000124, 0.000124, 0.000181)
                float physics:mass = 0.25
                quatf physics:principalAxes = (0.70710677, 0.70710677, 0, 0)

                over "cylinder_1" (
                    prepend apiSchemas = ["NewtonCollisionAPI"]
                )
                {
                }
            }

            over "base_camera_link" (
                prepend apiSchemas = ["PhysicsRigidBodyAPI", "PhysicsMassAPI"]
            )
            {
                point3f physics:centerOfMass = (0, 0, 0)
                float3 physics:diagonalInertia = (0.0000022, 0.0000022, 0.000003)
                float physics:mass = 0.02
                quatf physics:principalAxes = (1, 0, 0, 0)

                over "box_1" (
                    prepend apiSchemas = ["NewtonCollisionAPI"]
                )
                {
                }
            }

            over "box_1" (
                prepend apiSchemas = ["NewtonCollisionAPI"]
            )
            {
            }

            over "arm_mount_link" (
                prepend apiSchemas = ["PhysicsRigidBodyAPI", "PhysicsMassAPI"]
            )
            {
                point3f physics:centerOfMass = (0, 0, 0)
                float3 physics:diagonalInertia = (1e-9, 1e-9, 1e-9)
                float physics:mass = 0.001
                quatf physics:principalAxes = (1, 0, 0, 0)
            }
        }
    }

    over "Physics"
    {
        def PhysicsRevoluteJoint "wheel_front_left_joint" (
            prepend apiSchemas = ["PhysicsDriveAPI:angular", "PhysicsJointStateAPI:angular"]
        )
        {
            float drive:angular:physics:damping = 0.05
            uniform token physics:axis = "Y"
            custom rel physics:body0
            prepend rel physics:body0 = </sockbot_base/Geometry/base_link>
            custom rel physics:body1
            prepend rel physics:body1 = </sockbot_base/Geometry/base_link/wheel_front_left>
            point3f physics:localPos0 = (0.088, 0.1, 0)
            point3f physics:localPos1 = (0, 0, 0)
            quatf physics:localRot0 = (1, 0, 0, 0)
            quatf physics:localRot1 = (1, 0, 0, 0)
            custom float urdf:dynamics:damping = 0.05
            custom float urdf:dynamics:friction = 0
        }

        def PhysicsRevoluteJoint "wheel_front_right_joint" (
            prepend apiSchemas = ["PhysicsDriveAPI:angular", "PhysicsJointStateAPI:angular"]
        )
        {
            float drive:angular:physics:damping = 0.05
            uniform token physics:axis = "Y"
            custom rel physics:body0
            prepend rel physics:body0 = </sockbot_base/Geometry/base_link>
            custom rel physics:body1
            prepend rel physics:body1 = </sockbot_base/Geometry/base_link/wheel_front_right>
            point3f physics:localPos0 = (0.088, -0.1, 0)
            point3f physics:localPos1 = (0, 0, 0)
            quatf physics:localRot0 = (1, 0, 0, 0)
            quatf physics:localRot1 = (1, 0, 0, 0)
            custom float urdf:dynamics:damping = 0.05
            custom float urdf:dynamics:friction = 0
        }

        def PhysicsRevoluteJoint "wheel_rear_left_joint" (
            prepend apiSchemas = ["PhysicsDriveAPI:angular", "PhysicsJointStateAPI:angular"]
        )
        {
            float drive:angular:physics:damping = 0.05
            uniform token physics:axis = "Y"
            custom rel physics:body0
            prepend rel physics:body0 = </sockbot_base/Geometry/base_link>
            custom rel physics:body1
            prepend rel physics:body1 = </sockbot_base/Geometry/base_link/wheel_rear_left>
            point3f physics:localPos0 = (-0.088, 0.1, 0)
            point3f physics:localPos1 = (0, 0, 0)
            quatf physics:localRot0 = (1, 0, 0, 0)
            quatf physics:localRot1 = (1, 0, 0, 0)
            custom float urdf:dynamics:damping = 0.05
            custom float urdf:dynamics:friction = 0
        }

        def PhysicsRevoluteJoint "wheel_rear_right_joint" (
            prepend apiSchemas = ["PhysicsDriveAPI:angular", "PhysicsJointStateAPI:angular"]
        )
        {
            float drive:angular:physics:damping = 0.05
            uniform token physics:axis = "Y"
            custom rel physics:body0
            prepend rel physics:body0 = </sockbot_base/Geometry/base_link>
            custom rel physics:body1
            prepend rel physics:body1 = </sockbot_base/Geometry/base_link/wheel_rear_right>
            point3f physics:localPos0 = (-0.088, -0.1, 0)
            point3f physics:localPos1 = (0, 0, 0)
            quatf physics:localRot0 = (1, 0, 0, 0)
            quatf physics:localRot1 = (1, 0, 0, 0)
            custom float urdf:dynamics:damping = 0.05
            custom float urdf:dynamics:friction = 0
        }

        def PhysicsFixedJoint "arm_mount_joint"
        {
            custom rel physics:body0
            prepend rel physics:body0 = </sockbot_base/Geometry/base_link>
            custom rel physics:body1
            prepend rel physics:body1 = </sockbot_base/Geometry/base_link/arm_mount_link>
            point3f physics:localPos0 = (0.06, 0, 0.03)
            point3f physics:localPos1 = (0, 0, 0)
            quatf physics:localRot0 = (1, 0, 0, 0)
            quatf physics:localRot1 = (1, 0, 0, 0)
        }

        def PhysicsFixedJoint "base_camera_joint"
        {
            custom rel physics:body0
            prepend rel physics:body0 = </sockbot_base/Geometry/base_link>
            custom rel physics:body1
            prepend rel physics:body1 = </sockbot_base/Geometry/base_link/base_camera_link>
            point3f physics:localPos0 = (0.11, 0, 0.007)
            point3f physics:localPos1 = (0, 0, 0)
            quatf physics:localRot0 = (1, 0, 0, 0)
            quatf physics:localRot1 = (1, 0, 0, 0)
        }
    }
}

